<?xml version="1.0" ?>
<!-- =================================================================================== -->
<!-- |    This document was autogenerated by xacro from urdf/pioneer3at.urdf.xacro     | -->
<!-- |    EDITING THIS FILE BY HAND IS NOT RECOMMENDED                                 | -->
<!-- =================================================================================== -->
<!--
  Pioneer 3-AT - descrição URDF/xacro para ROS 2 Humble + Gazebo Harmonic.

  Diferente do URDF antigo (que era SÓ visual e "não carregava no Gazebo"),
  este arquivo descreve o robô como um corpo físico:
    - <visual>    : a aparência (malhas STL reaproveitadas de meshes/)
    - <collision> : a forma usada pela física (primitivas simples: caixa/cilindro)
    - <inertial>  : massa + tensor de inércia (necessário p/ o robô se mover de verdade)

  Convenção de coordenadas:
    base_link tem origem no NÍVEL DO CHÃO, no centro do robô. O chassi é desenhado
    0.177 m acima, e os centros das rodas ficam a 0.111 m (raio 0.11 -> tocam o chão).

  Os blocos <gazebo> com os plugins (tração, juntas) e o sensor LiDAR são
  adicionados nas fases seguintes da migração.
-->
<robot name="pioneer3at">
  <!-- ============================================================= -->
  <!-- Materiais (cores para RViz e Gazebo)                          -->
  <!-- ============================================================= -->
  <material name="ChassisRed">
    <color rgba="0.851 0.0 0.0 1.0"/>
  </material>
  <material name="TopBlack">
    <color rgba="0.038 0.038 0.038 1.0"/>
  </material>
  <material name="AxleGrey">
    <color rgba="0.5 0.5 0.5 1.0"/>
  </material>
  <material name="HubcapYellow">
    <color rgba="1.0 0.811 0.151 1.0"/>
  </material>
  <material name="WheelBlack">
    <color rgba="0.117 0.117 0.117 1.0"/>
  </material>
  <material name="SonarYellow">
    <color rgba="0.715 0.583 0.210 1.0"/>
  </material>
  <!-- ============================================================= -->
  <!-- Chassi (base_link) - link raiz                                -->
  <!-- ============================================================= -->
  <link name="base_link">
    <visual>
      <origin rpy="0 0 0" xyz="0 0 0.177"/>
      <geometry>
        <mesh filename="package://pioneer3at/meshes/chassis.stl"/>
      </geometry>
      <material name="ChassisRed"/>
    </visual>
    <!-- Colisão: caixa simples (0.501 x 0.400 x 0.190), do modelo antigo -->
    <collision>
      <origin rpy="0 0 0" xyz="0 0 0.177"/>
      <geometry>
        <box size="0.501 0.400 0.190"/>
      </geometry>
    </collision>
    <!-- Inércia do chassi reaproveitada do modelo antigo (massa 14 kg) -->
    <inertial>
      <origin rpy="0 0 0" xyz="0 0 0.177"/>
      <mass value="14.0"/>
      <inertia ixx="0.3338" ixy="0.0" ixz="0.0" iyy="0.4783" iyz="0.0" izz="0.3338"/>
    </inertial>
  </link>
  <!-- ============================================================= -->
  <!-- Top plate (placa superior) - fixa ao chassi                  -->
  <!-- ============================================================= -->
  <link name="top_plate">
    <visual>
      <origin rpy="0 0 0" xyz="0 0 0"/>
      <geometry>
        <mesh filename="package://pioneer3at/meshes/top.stl"/>
      </geometry>
      <material name="TopBlack"/>
    </visual>
    <inertial>
      <mass value="0.5"/>
      <inertia ixx="0.0067" ixy="0.0" ixz="0.0" iyy="0.0067" iyz="0.0" izz="0.0133"/>
    </inertial>
  </link>
  <joint name="base_top_joint" type="fixed">
    <origin rpy="0 0 0" xyz="0.003 0 0.274"/>
    <parent link="base_link"/>
    <child link="top_plate"/>
  </joint>
  <link name="front_left_wheel">
    <!-- malha do eixo (axle) -->
    <visual>
      <origin rpy="0 0 0" xyz="0 0 0"/>
      <geometry>
        <mesh filename="package://pioneer3at/meshes/axle.stl"/>
      </geometry>
      <material name="AxleGrey"/>
    </visual>
    <!-- malha do cubo (hub) -->
    <visual>
      <origin rpy="0.0 0 0" xyz="0 0.041 0"/>
      <geometry>
        <mesh filename="package://pioneer3at/meshes/hub.stl"/>
      </geometry>
      <material name="HubcapYellow"/>
    </visual>
    <!-- malha do pneu (wheel) -->
    <visual>
      <origin rpy="0 0 0" xyz="0 0.041 0"/>
      <geometry>
        <mesh filename="package://pioneer3at/meshes/wheel.stl"/>
      </geometry>
      <material name="WheelBlack"/>
    </visual>
    <!-- colisão: cilindro alinhado ao eixo Y (rpy gira Z->Y) -->
    <collision>
      <origin rpy="1.5708 0 0" xyz="0 0.041 0"/>
      <geometry>
        <cylinder length="0.075" radius="0.11"/>
      </geometry>
    </collision>
    <inertial>
      <origin rpy="0 0 0" xyz="0 0.041 0"/>
      <mass value="1.5"/>
      <!-- transverse = 1/12 m (3r^2 + l^2) ; axial(Y) = 1/2 m r^2 -->
      <inertia ixx="0.005240625" ixy="0.0" ixz="0.0" iyy="0.009075" iyz="0.0" izz="0.005240625"/>
    </inertial>
  </link>
  <!-- junta CONTÍNUA: agora a roda gira de verdade (eixo Y) -->
  <joint name="front_left_wheel_joint" type="continuous">
    <origin rpy="0 0 0" xyz="0.135 0.156 0.111"/>
    <parent link="base_link"/>
    <child link="front_left_wheel"/>
    <axis xyz="0 1 0"/>
    <limit effort="100.0" velocity="20.0"/>
    <dynamics damping="0.1" friction="0.1"/>
  </joint>
  <link name="front_right_wheel">
    <!-- malha do eixo (axle) -->
    <visual>
      <origin rpy="0 0 0" xyz="0 0 0"/>
      <geometry>
        <mesh filename="package://pioneer3at/meshes/axle.stl"/>
      </geometry>
      <material name="AxleGrey"/>
    </visual>
    <!-- malha do cubo (hub) -->
    <visual>
      <origin rpy="-3.14 0 0" xyz="0 -0.041 0"/>
      <geometry>
        <mesh filename="package://pioneer3at/meshes/hub.stl"/>
      </geometry>
      <material name="HubcapYellow"/>
    </visual>
    <!-- malha do pneu (wheel) -->
    <visual>
      <origin rpy="0 0 0" xyz="0 -0.041 0"/>
      <geometry>
        <mesh filename="package://pioneer3at/meshes/wheel.stl"/>
      </geometry>
      <material name="WheelBlack"/>
    </visual>
    <!-- colisão: cilindro alinhado ao eixo Y (rpy gira Z->Y) -->
    <collision>
      <origin rpy="1.5708 0 0" xyz="0 -0.041 0"/>
      <geometry>
        <cylinder length="0.075" radius="0.11"/>
      </geometry>
    </collision>
    <inertial>
      <origin rpy="0 0 0" xyz="0 -0.041 0"/>
      <mass value="1.5"/>
      <!-- transverse = 1/12 m (3r^2 + l^2) ; axial(Y) = 1/2 m r^2 -->
      <inertia ixx="0.005240625" ixy="0.0" ixz="0.0" iyy="0.009075" iyz="0.0" izz="0.005240625"/>
    </inertial>
  </link>
  <!-- junta CONTÍNUA: agora a roda gira de verdade (eixo Y) -->
  <joint name="front_right_wheel_joint" type="continuous">
    <origin rpy="0 0 0" xyz="0.135 -0.156 0.111"/>
    <parent link="base_link"/>
    <child link="front_right_wheel"/>
    <axis xyz="0 1 0"/>
    <limit effort="100.0" velocity="20.0"/>
    <dynamics damping="0.1" friction="0.1"/>
  </joint>
  <link name="rear_left_wheel">
    <!-- malha do eixo (axle) -->
    <visual>
      <origin rpy="0 0 0" xyz="0 0 0"/>
      <geometry>
        <mesh filename="package://pioneer3at/meshes/axle.stl"/>
      </geometry>
      <material name="AxleGrey"/>
    </visual>
    <!-- malha do cubo (hub) -->
    <visual>
      <origin rpy="0.0 0 0" xyz="0 0.041 0"/>
      <geometry>
        <mesh filename="package://pioneer3at/meshes/hub.stl"/>
      </geometry>
      <material name="HubcapYellow"/>
    </visual>
    <!-- malha do pneu (wheel) -->
    <visual>
      <origin rpy="0 0 0" xyz="0 0.041 0"/>
      <geometry>
        <mesh filename="package://pioneer3at/meshes/wheel.stl"/>
      </geometry>
      <material name="WheelBlack"/>
    </visual>
    <!-- colisão: cilindro alinhado ao eixo Y (rpy gira Z->Y) -->
    <collision>
      <origin rpy="1.5708 0 0" xyz="0 0.041 0"/>
      <geometry>
        <cylinder length="0.075" radius="0.11"/>
      </geometry>
    </collision>
    <inertial>
      <origin rpy="0 0 0" xyz="0 0.041 0"/>
      <mass value="1.5"/>
      <!-- transverse = 1/12 m (3r^2 + l^2) ; axial(Y) = 1/2 m r^2 -->
      <inertia ixx="0.005240625" ixy="0.0" ixz="0.0" iyy="0.009075" iyz="0.0" izz="0.005240625"/>
    </inertial>
  </link>
  <!-- junta CONTÍNUA: agora a roda gira de verdade (eixo Y) -->
  <joint name="rear_left_wheel_joint" type="continuous">
    <origin rpy="0 0 0" xyz="-0.135 0.156 0.111"/>
    <parent link="base_link"/>
    <child link="rear_left_wheel"/>
    <axis xyz="0 1 0"/>
    <limit effort="100.0" velocity="20.0"/>
    <dynamics damping="0.1" friction="0.1"/>
  </joint>
  <link name="rear_right_wheel">
    <!-- malha do eixo (axle) -->
    <visual>
      <origin rpy="0 0 0" xyz="0 0 0"/>
      <geometry>
        <mesh filename="package://pioneer3at/meshes/axle.stl"/>
      </geometry>
      <material name="AxleGrey"/>
    </visual>
    <!-- malha do cubo (hub) -->
    <visual>
      <origin rpy="-3.14 0 0" xyz="0 -0.041 0"/>
      <geometry>
        <mesh filename="package://pioneer3at/meshes/hub.stl"/>
      </geometry>
      <material name="HubcapYellow"/>
    </visual>
    <!-- malha do pneu (wheel) -->
    <visual>
      <origin rpy="0 0 0" xyz="0 -0.041 0"/>
      <geometry>
        <mesh filename="package://pioneer3at/meshes/wheel.stl"/>
      </geometry>
      <material name="WheelBlack"/>
    </visual>
    <!-- colisão: cilindro alinhado ao eixo Y (rpy gira Z->Y) -->
    <collision>
      <origin rpy="1.5708 0 0" xyz="0 -0.041 0"/>
      <geometry>
        <cylinder length="0.075" radius="0.11"/>
      </geometry>
    </collision>
    <inertial>
      <origin rpy="0 0 0" xyz="0 -0.041 0"/>
      <mass value="1.5"/>
      <!-- transverse = 1/12 m (3r^2 + l^2) ; axial(Y) = 1/2 m r^2 -->
      <inertia ixx="0.005240625" ixy="0.0" ixz="0.0" iyy="0.009075" iyz="0.0" izz="0.005240625"/>
    </inertial>
  </link>
  <!-- junta CONTÍNUA: agora a roda gira de verdade (eixo Y) -->
  <joint name="rear_right_wheel_joint" type="continuous">
    <origin rpy="0 0 0" xyz="-0.135 -0.156 0.111"/>
    <parent link="base_link"/>
    <child link="rear_right_wheel"/>
    <axis xyz="0 1 0"/>
    <limit effort="100.0" velocity="20.0"/>
    <dynamics damping="0.1" friction="0.1"/>
  </joint>
  <!-- ============================================================= -->
  <!-- Sonares (apenas visuais/decorativos)                          -->
  <!-- ============================================================= -->
  <link name="front_sonar">
    <visual>
      <origin rpy="0 0 0" xyz="0 0 0"/>
      <geometry>
        <mesh filename="package://pioneer3at/meshes/front_sonar.stl"/>
      </geometry>
      <material name="SonarYellow"/>
    </visual>
    <inertial>
      <mass value="0.1"/>
      <inertia ixx="0.0001" ixy="0.0" ixz="0.0" iyy="0.0001" iyz="0.0" izz="0.0001"/>
    </inertial>
  </link>
  <joint name="front_sonar_joint" type="fixed">
    <origin rpy="0 0 0" xyz="0.193 0 0.25"/>
    <parent link="base_link"/>
    <child link="front_sonar"/>
  </joint>
  <link name="rear_sonar">
    <visual>
      <origin rpy="0 0 0" xyz="0 0 0"/>
      <geometry>
        <mesh filename="package://pioneer3at/meshes/back_sonar.stl"/>
      </geometry>
      <material name="SonarYellow"/>
    </visual>
    <inertial>
      <mass value="0.1"/>
      <inertia ixx="0.0001" ixy="0.0" ixz="0.0" iyy="0.0001" iyz="0.0" izz="0.0001"/>
    </inertial>
  </link>
  <joint name="rear_sonar_joint" type="fixed">
    <origin rpy="0 0 0" xyz="-0.187 0 0.247"/>
    <parent link="base_link"/>
    <child link="rear_sonar"/>
  </joint>
  <!-- ============================================================= -->
  <!-- LiDAR (Hokuyo) - montado no topo dianteiro                    -->
  <!-- base_link tem origem no chão; z=0.30 fica logo acima do topo. -->
  <!-- ============================================================= -->
  <link name="lidar_link">
    <visual>
      <origin rpy="0 0 0" xyz="0 0 0"/>
      <geometry>
        <box size="0.05 0.05 0.07"/>
      </geometry>
      <material name="TopBlack"/>
    </visual>
    <collision>
      <geometry>
        <box size="0.05 0.05 0.07"/>
      </geometry>
    </collision>
    <inertial>
      <mass value="0.13"/>
      <inertia ixx="0.0001" ixy="0.0" ixz="0.0" iyy="0.0001" iyz="0.0" izz="0.0001"/>
    </inertial>
  </link>
  <joint name="lidar_joint" type="fixed">
    <origin rpy="0 0 0" xyz="0.15 0 0.30"/>
    <parent link="base_link"/>
    <child link="lidar_link"/>
  </joint>
  <!-- ============================================================= -->
  <!-- Plugins do Gazebo Harmonic (gz-sim)                           -->
  <!-- Um <gazebo> sem 'reference' aplica-se ao modelo todo.         -->
  <!-- ============================================================= -->
  <gazebo>
    <!-- Tração: DiffDrive em modo skid-steer (2 juntas por lado).
         Consome /cmd_vel e publica /odom + TF odom->base_link. -->
    <plugin filename="gz-sim-diff-drive-system" name="gz::sim::systems::DiffDrive">
      <left_joint>front_left_wheel_joint</left_joint>
      <left_joint>rear_left_wheel_joint</left_joint>
      <right_joint>front_right_wheel_joint</right_joint>
      <right_joint>rear_right_wheel_joint</right_joint>
      <wheel_separation>0.4</wheel_separation>
      <wheel_radius>0.11</wheel_radius>
      <!-- Limites cinemáticos do Pioneer 3-AT real (datasheet):
           0.7 m/s de velocidade linear e ~140 deg/s (2.44 rad/s) de rotação. -->
      <max_linear_velocity>0.7</max_linear_velocity>
      <max_angular_velocity>2.44</max_angular_velocity>
      <max_linear_acceleration>0.3</max_linear_acceleration>
      <min_linear_acceleration>-0.3</min_linear_acceleration>
      <max_angular_acceleration>1.57</max_angular_acceleration>
      <min_angular_acceleration>-1.57</min_angular_acceleration>
      <topic>cmd_vel</topic>
      <odom_topic>odom</odom_topic>
      <tf_topic>tf</tf_topic>
      <frame_id>odom</frame_id>
      <child_frame_id>base_link</child_frame_id>
      <odom_publish_frequency>30</odom_publish_frequency>
    </plugin>
    <!-- Publica o estado (posição/velocidade) de todas as juntas -->
    <plugin filename="gz-sim-joint-state-publisher-system" name="gz::sim::systems::JointStatePublisher">
      <topic>joint_states</topic>
    </plugin>
  </gazebo>
  <!-- Sensor LiDAR no lidar_link (renderizado pelo plugin Sensors do mundo).
       Parâmetros reaproveitados do Hokuyo do modelo antigo. -->
  <gazebo reference="lidar_link">
    <sensor name="hokuyo" type="gpu_lidar">
      <topic>scan</topic>
      <gz_frame_id>lidar_link</gz_frame_id>
      <update_rate>10</update_rate>
      <always_on>1</always_on>
      <visualize>true</visualize>
      <lidar>
        <scan>
          <horizontal>
            <samples>640</samples>
            <resolution>1</resolution>
            <min_angle>-2.2689</min_angle>
            <max_angle>2.2689</max_angle>
          </horizontal>
        </scan>
        <range>
          <min>0.08</min>
          <max>10.0</max>
          <resolution>0.01</resolution>
        </range>
      </lidar>
    </sensor>
  </gazebo>
</robot>
